Workbook

Sheet COMO USAR
A1: COMO USAR ESTA PLANILHA — Cronograma MPMS (Analista TI / Desenvolvimento de Sistemas)
A2: Guia rápido de cada aba — o que preencher, o que é automático e a ordem de uso no dia a dia
A4: 1. DIÁRIO DE ESTUDO — comece por aqui todo dia
A5: • É o coração da planilha. Cada linha é uma tarefa: matéria + assunto do dia, já organizados por rodízio (nunca fica só numa matéria).
A6: • As linhas de tipo REVISÃO 24H / 7 DIAS / 15 DIAS / 30 DIAS aparecem sozinhas nas datas certas — é o sistema de revisão espaçada (o que você estuda hoje, volta a aparecer em 1, 7, 15 e 30 dias).
A7: • TODO DIA, depois de estudar: preencha só as colunas QUESTÕES (quantas fez) e ACERTOS (quantas acertou) na linha do assunto correspondente.
A8: • Não precisa mexer em mais nada nessa aba — data, matéria e assunto já vêm prontos.
A10: 2. EDITAL — checklist de tudo que cai na prova
A11: • Lista todos os assuntos do cargo, agrupados por matéria, com um status: SIM / NÃO / ATENÇÃO / PRECISO ESTUDAR / DOMINO / CAIU NA ÚLTIMA PROVA.
A12: • Marque 'MATÉRIA ESTUDADA', 'AULAS/TEORIA' e 'JÁ FIZ QUESTÕES?' para cada assunto conforme for avançando — a célula muda de cor sozinha (verde = SIM, vermelho = NÃO, etc.).
A13: • As colunas QTD. EXERC. e ACERTOS NÃO se preenchem aqui — elas somam sozinhas o que você lançou no Diário de estudo para aquele mesmo assunto.
A14: • DESEMP. (%) é automático (acertos ÷ questões). REVISÃO 1º/2º/3º: preencha a data em que revisou aquele assunto especificamente (além das revisões automáticas do Diário).
... A49: 6) Uma vez por semana, dê uma olhada no Controle de Questões e na Dica de Horas de Estudo para ver se está equilibrado entre as matérias.

Sheet TÉCNICAS DE ESTUDO
A1: TÉCNICAS DE ESTUDO — o que a ciência mostra que funciona
A2: Baseado na revisão de Dunlosky, Rawson, Marsh, Nathan & Willingham (2013), a mais citada sobre eficácia de técnicas de aprendizagem
A4: LEGENDA DE EFICÁCIA:
A5: ALTA — priorize sempre
A7: MODERADA — bom complemento
A9: BAIXA — evite usar sozinha
A11: EFICÁCIA | B11: TÉCNICA | C11: O QUE É E POR QUE FUNCIONA | D11: COMO JÁ ESTÁ NA SUA PLANILHA / RECOMENDAÇÃO
A12: ALTA | B12: Active Recall (prática de recuperação) | C12: Testar-se ativamente sobre o conteúdo — fechar o material e tentar lembrar, responder questões, recitar em voz alta — em vez de reler ou apenas assistir aula. É a técnica com maior efeito comprovado sobre retenção de longo prazo, porque força o cérebro a reconstruir a informação, e não só reconhecê-la. | D12: Na planilha: aba EDITAL (marcar 'já fiz questões') e Diário de estudo (bloco de questões todo dia, antes de considerar o assunto 'dominado').
A13: ALTA | B13: Repetição Espaçada (Spaced Repetition) | C13: Revisar o mesmo conteúdo em intervalos crescentes (ex.: 1, 7, 15, 30 dias) em vez de estudar tudo de uma vez e nunca mais voltar. Cada revisão no momento certo (pouco antes de esquecer) fortalece a memória de longo prazo muito mais que reestudar tudo de uma vez (cramming). | D13: Na planilha: aba Diário de estudo já gera automaticamente as linhas de REVISÃO 24H / 7 DIAS / 15 DIAS / 30 DIAS para cada assunto estudado.
A14: ALTA | B14: Intercalação (Interleaving) | C14: Misturar matérias ou tipos de problema numa mesma sessão de estudo, em vez de estudar um assunto isolado até exaustão (blocked practice). Aumenta o esforço mental no curto prazo (parece mais difícil), mas melhora a capacidade de diferenciar e aplicar o conhecimento certo na hora certa — o que é exatamente o que uma prova de concurso exige. | D14: Na planilha: o cronograma já roda em rodízio entre as matérias, nunca em blocos fechados de uma matéria só.
A15: MODERADA | B15: Elaboração (Elaborative Interrogation / Self-Explanation) | C15: Perguntar e responder 'por quê' e 'como' sobre o conteúdo, em vez de só memorizar o 'o quê'. Explicar com suas próprias palavras por que uma resposta está certa cria conexões mais profundas com o que você já sabe. | D15: Na planilha: campo 'Fundamento da resposta certa' no Caderno de Erros.
A16: MODERADA | B16: Exemplos Concretos (Concrete Examples) | C16: Associar conceitos abstratos a exemplos e situações reais e específicas. Ajuda a lembrar e a transferir o conhecimento para questões com contextos diferentes do material original. | D16: Na prática: ao estudar Direito Administrativo/Legislação, relacione com situações reais do setor público que você já vivencia no trabalho.
A17: MODERADA | B17: Prática Distribuída (Distributed Practice) | C17: Estudar em sessões mais curtas e frequentes ao longo do tempo, em vez de sessões longas e raras. É o princípio por trás da repetição espaçada aplicado à carga horária diária. | D17: Na planilha: rotina de 2h em dias úteis + 4h no fim de semana, em vez de tentar concentrar tudo em uma única maratona.
A18: BAIXA | B18: Releitura (Rereading) | C18: Ler o mesmo material várias vezes. Dá uma falsa sensação de domínio (familiaridade é confundida com aprendizado), mas o efeito real sobre a retenção é fraco quando usada sozinha, sem teste ativo. | D18: Uso recomendado: só como primeiro contato com o conteúdo, nunca como método principal de revisão — substitua por active recall.
A19: BAIXA | B19: Grifar e Destacar (Highlighting/Underlining) | C19: Marcar trechos do texto como importantes. É passivo, exige pouco esforço cognitivo e não força a reorganização da informação na memória — por isso o efeito comprovado é baixo. | D19: Uso recomendado: pode ajudar a localizar informação depois, mas não substitui fazer questões ou se testar sobre o trecho grifado.
A20: BAIXA | B20: Resumos (Summarization) | C20: Reescrever o conteúdo de forma condensada. Funciona razoavelmente bem para quem já sabe resumir bem (identificar o que é essencial), mas tem eficácia inconsistente e é uma habilidade que a maioria das pessoas não domina bem. | D20: Uso recomendado: útil para organizar o material antes de estudar, mas não é revisão — depois do resumo pronto, teste-se sobre ele com active recall.
A22: RESUMO PRÁTICO
A23: • Priorize sempre: fazer questões (active recall) + revisar em intervalos crescentes (repetição espaçada) + misturar matérias (intercalação).
A24: • O erro mais comum é inverter a ordem: estudar teoria exaustivamente e deixar questões só para o fim. O ideal é começar a fazer questões cedo, mesmo errando muito no início — o erro guiado é parte do aprendizado.
A25: • Releitura, grifar e resumir sozinhos dão sensação de progresso, mas retêm pouco. Use-os só como preparação, nunca como substituto de se testar.
A26: • Essa planilha já foi montada em cima das técnicas de alta eficácia: o rodízio de matérias é intercalação, as linhas de REVISÃO 24H/7D/15D/30D no Diário são repetição espaçada, e o Controle de Questões + Caderno de Erros existem para forçar prática ativa.
A28: Fonte: Dunlosky, J., Rawson, K. A., Marsh, E. J., Nathan, M. J., & Willingham, D. T. (2013). Improving Students' Learning With Effective Learning Techniques. Psychological Science in the Public Interest, 14(1), 4–58.

Sheet Diário de estudo
A1: DIÁRIO DE ESTUDO — preencha QUESTÕES e ACERTOS aqui; as outras abas somam sozinhas
A2: DATA | B2: DIA DA SEMANA | C2: Nº | D2: MATÉRIA | E2: TIPO | F2: ASSUNTO / ATIVIDADE | G2: CH (MIN) | H2: QUESTÕES | I2: ACERTOS | J2: STATUS
A3: 46283 | B3: Sexta | C3: 1 | D3: LÍNGUA PORTUGUESA | E3: ESTUDO | F3: Interpretação de texto, tipologia e gêneros textuais | G3: 120 | J3: A FAZER
A4: 46284 | B4: Sábado | C4: 2 | D4: DIREITO CONSTITUCIONAL | E4: ESTUDO | F4: Constitucionalismo, conceito e classificação das Constituições | G4: 120 | J4: A FAZER
A5: 46284 | B5: Sábado | C5: 3 | D5: DIREITO ADMINISTRATIVO | E5: ESTUDO | F5: Princípios e Poderes Administrativos | G5: 120 | J5: A FAZER
A6: 46284 | B6: Sábado | C6: 4 | D6: LÍNGUA PORTUGUESA | E6: REVISÃO 24H | F6: Interpretação de texto, tipologia e gêneros textuais | J6: A FAZER
A7: 46285 | B7: Domingo | C7: 5 | D7: LEGISLAÇÃO INSTITUCIONAL MP | E7: ESTUDO | F7: Lei Orgânica Nacional do MP (Lei 8.625/93) | G7: 120 | J7: A FAZER
A8: 46285 | B8: Domingo | C8: 6 | D8: ENGENHARIA DE SOFTWARE | E8: SIMULADO | F8: Simulado misto (questões de todas as matérias da semana) | G8: 120 | J8: A FAZER
A9: 46285 | B9: Domingo | C9: 7 | D9: DIREITO CONSTITUCIONAL | E9: REVISÃO 24H | F9: Constitucionalismo, conceito e classificação das Constituições | J9: A FAZER
A10: 46285 | B10: Domingo | C10: 8 | D10: DIREITO ADMINISTRATIVO | E10: REVISÃO 24H | F10: Princípios e Poderes Administrativos | J10: A FAZER
A11: 46286 | B11: Segunda | C11: 9 | D11: ARQUITETURA DE SOFTWARE | E11: ESTUDO | F11: Padrão MVC; Microsserviços; Arquitetura orientada a eventos | G11: 120 | J11: A FAZER
A12: 46286 | B12: Segunda | C12: 10 | D12: LEGISLAÇÃO INSTITUCIONAL MP | E12: REVISÃO 24H | F12: Lei Orgânica Nacional do MP (Lei 8.625/93) | J12: A FAZER
A13: 46287 | B13: Terça | C13: 11 | D13: LINGUAGENS DE PROGRAMAÇÃO | E13: ESTUDO | F13: Orientação a Objetos: pilares e características estruturais | G13: 120 | J13: A FAZER
A14: 46287 | B14: Terça | C14: 12 | D14: ARQUITETURA DE SOFTWARE | E14: REVISÃO 24H | F14: Padrão MVC; Microsserviços; Arquitetura orientada a eventos | J14: A FAZER
A15: 46288 | B15: Quarta | C15: 13 | D15: QUALIDADE DE SOFTWARE | E15: ESTUDO | F15: Garantia da qualidade e métricas de código | G15: 120 | J15: A FAZER
A16: 46288 | B16: Quarta | C16: 14 | D16: LINGUAGENS DE PROGRAMAÇÃO | E16: REVISÃO 24H | F16: Orientação a Objetos: pilares e características estruturais | J16: A FAZER
A17: 46289 | B17: Quinta | C17: 15 | D17: ESTRUTURA DE DADOS E ALGORITMOS | E17: ESTUDO | F17: Tipos básicos e abstratos de dados (lista, fila, pilha, árvore) | G17: 120 | J17: A FAZER
A18: 46289 | B18: Quinta | C18: 16 | D18: QUALIDADE DE SOFTWARE | E18: REVISÃO 24H | F18: Garantia da qualidade e métricas de código | J18: A FAZER
A19: 46290 | B19: Sexta | C19: 17 | D19: ARQUITETURA / BANCO DE DADOS | E19: ESTUDO | F19: Modelagem de dados: conceitual, lógica e física | G19: 120 | J19: A FAZER
A20: 46290 | B20: Sexta | C20: 18 | D20: LÍNGUA PORTUGUESA | E20: REVISÃO 7 DIAS | F20: Interpretação de texto, tipologia e gêneros textuais | J20: A FAZER
A21: 46290 | B21: Sexta | C21: 19 | D21: ESTRUTURA DE DADOS E ALGORITMOS | E21: REVISÃO 24H | F21: Tipos básicos e abstratos de dados (lista, fila, pilha, árvore) | J21: A FAZER
A22: 46291 | B22: Sábado | C22: 20 | D22: SEGURANÇA DA INFORMAÇÃO | E22: ESTUDO | F22: Desenvolvimento seguro: SAST / DAST / IAST | G22: 120 | J22: A FAZER
A23: 46291 | B23: Sábado | C23: 21 | D23: ENGENHARIA DE SOFTWARE | E23: ESTUDO | F23: Ciclo de vida e metodologias de desenvolvimento (cascata, ágil) | G23: 120 | J23: A FAZER
A24: 46291 | B24: Sábado | C24: 22 | D24: DIREITO CONSTITUCIONAL | E24: REVISÃO 7 DIAS | F24: Constitucionalismo, conceito e classificação das Constituições | J24: A FAZER
A25: 46291 | B25: Sábado | C25: 23 | D25: DIREITO ADMINISTRATIVO | E25: REVISÃO 7 DIAS | F25: Princípios e Poderes Administrativos | J25: A FAZER
A26: 46291 | B26: Sábado | C26: 24 | D26: ARQUITETURA / BANCO DE DADOS | E26: REVISÃO 24H | F26: Modelagem de dados: conceitual, lógica e física | J26: A FAZER
A27: 46292 | B27: Domingo | C27: 25 | D27: ARQUITETURA DE SOFTWARE | E27: ESTUDO | F27: Arquitetura Orientada a Serviços (SOA) e interoperabilidade | G27: 120 | J27: A FAZER
A28: 46292 | B28: Domingo | C28: 26 | D28: LINGUAGENS DE PROGRAMAÇÃO | E28: SIMULADO | F28: Simulado misto (questões de todas as matérias da semana) | G28: 120 | J28: A FAZER
A29: 46292 | B29: Domingo | C29: 27 | D29: LEGISLAÇÃO INSTITUCIONAL MP | E29: REVISÃO 7 DIAS | F29: Lei Orgânica Nacional do MP (Lei 8.625/93) | J29: A FAZER
A30: 46292 | B30: Domingo | C30: 28 | D30: SEGURANÇA DA INFORMAÇÃO | E30: REVISÃO 24H | F30: Desenvolvimento seguro: SAST / DAST / IAST | J30: A FAZER
A31: 46292 | B31: Domingo | C31: 29 | D31: ENGENHARIA DE SOFTWARE | E31: REVISÃO 24H | F31: Ciclo de vida e metodologias de desenvolvimento (cascata, ágil) | J31: A FAZER
A32: 46293 | B32: Segunda | C32: 30 | D32: ESTRUTURA DE DADOS E ALGORITMOS | E32: ESTUDO | F32: Sub-rotinas: chamada por endereço, referência e valor | G32: 120 | J32: A FAZER
A33: 46293 | B33: Segunda | C33: 31 | D33: ARQUITETURA DE SOFTWARE | E33: REVISÃO 7 DIAS | F33: Padrão MVC; Microsserviços; Arquitetura orientada a eventos | J33: A FAZER
A34: 46293 | B34: Segunda | C34: 32 | D34: ARQUITETURA DE SOFTWARE | E34: REVISÃO 24H | F34: Arquitetura Orientada a Serviços (SOA) e interoperabilidade | J34: A FAZER
A35: 46294 | B35: Terça | C35: 33 | D35: ARQUITETURA / BANCO DE DADOS | E35: ESTUDO | F35: Normalização, integridade referencial e metadados | G35: 120 | J35: A FAZER
A36: 46294 | B36: Terça | C36: 34 | D36: LINGUAGENS DE PROGRAMAÇÃO | E36: REVISÃO 7 DIAS | F36: Orientação a Objetos: pilares e características estruturais | J36: A FAZER
A37: 46294 | B37: Terça | C37: 35 | D37: ESTRUTURA DE DADOS E ALGORITMOS | E37: REVISÃO 24H | F37: Sub-rotinas: chamada por endereço, referência e valor | J37: A FAZER
A38: 46295 | B38: Quarta | C38: 36 | D38: LÍNGUA PORTUGUESA | E38: ESTUDO | F38: Ortografia, acentuação e uso da crase | G38: 120 | J38: A FAZER
A39: 46295 | B39: Quarta | C39: 37 | D39: QUALIDADE DE SOFTWARE | E39: REVISÃO 7 DIAS | F39: Garantia da qualidade e métricas de código | J39: A FAZER
A40: 46295 | B40: Quarta | C40: 38 | D40: ARQUITETURA / BANCO DE DADOS | E40: REVISÃO 24H | F40: Normalização, integridade referencial e metadados | J40: A FAZER
...

Sheet EDITAL
A1: CONCURSO MPMS — ANALISTA DE TI / DESENVOLVIMENTO DE SISTEMAS (base: Edital nº 1/2022-MPMS)
A2: Cronograma adaptado — atualizar quando sair o novo edital | Quantidade/Acertos vêm automaticamente do 'Diário de estudo'
A4: LEGENDA: | B4: SIM | C4: NÃO | D4: ATENÇÃO | E4: PRECISO ESTUDAR | F4: DOMINO | G4: CAIU NA ÚLTIMA PROVA
A6: LÍNGUA PORTUGUESA | K6: =IFERROR(COUNTIF(B7:B12,"SIM")/COUNTA(B7:B12),0) | L6: MATEI NO DIÁRIO?
B7: MATÉRIA ESTUDADA | C7: AULAS / TEORIA | D7: JÁ FIZ QUESTÕES? | E7: QTD. EXERC. | F7: ACERTOS | G7: DESEMP. (%) | H7: REVISÃO 1º | I7: REVISÃO 2º | J7: REVISÃO 3º | K7: ANOTAÇÕES
A8: Interpretação de texto, tipologia e gêneros textuais | B8: NÃO | C8: NÃO | D8: NÃO | E8: =SUMIFS('Diário de estudo'!H3:H530,'Diário de estudo'!D3:D530,"LÍNGUA PORTUGUESA",'Diário de estudo'!F3:F530,A8) | F8: =SUMIFS('Diário de estudo'!I3:I530,'Diário de estudo'!D3:D530,"LÍNGUA PORTUGUESA",'Diário de estudo'!F3:F530,A8) | G8: =IFERROR(F8/E8,"") | L8: =IF(COUNTIFS('Diário de estudo'!$D$3:$D$530,"LÍNGUA PORTUGUESA",'Diário de estudo'!$F$3:$F$530,A8,'Diário de estudo'!$J$3:$J$530,"CONCLUÍDO")>0,"✔ SIM","—")
A9: Ortografia, acentuação e uso da crase | B9: NÃO | C9: NÃO | D9: NÃO | E9: =SUMIFS('Diário de estudo'!H3:H530,'Diário de estudo'!D3:D530,"LÍNGUA PORTUGUESA",'Diário de estudo'!F3:F530,A9) | F9: =SUMIFS('Diário de estudo'!I3:I530,'Diário de estudo'!D3:D530,"LÍNGUA PORTUGUESA",'Diário de estudo'!F3:F530,A9) | G9: =IFERROR(F9/E9,"") | L9: =IF(COUNTIFS('Diário de estudo'!$D$3:$D$530,"LÍNGUA PORTUGUESA",'Diário de estudo'!$F$3:$F$530,A9,'Diário de estudo'!$J$3:$J$530,"CONCLUÍDO")>0,"✔ SIM","—")
A10: Morfologia (classes de palavras) e funções do 'que'/'se' | B10: NÃO | C10: NÃO | D10: NÃO | E10: =SUMIFS('Diário de estudo'!H3:H530,'Diário de estudo'!D3:D530,"LÍNGUA PORTUGUESA",'Diário de estudo'!F3:F530,A10) | F10: =SUMIFS('Diário de estudo'!I3:I530,'Diário de estudo'!D3:D530,"LÍNGUA PORTUGUESA",'Diário de estudo'!F3:F530,A10) | G10: =IFERROR(F10/E10,"") | L10: =IF(COUNTIFS('Diário de estudo'!$D$3:$D$530,"LÍNGUA PORTUGUESA",'Diário de estudo'!$F$3:$F$530,A10,'Diário de estudo'!$J$3:$J$530,"CONCLUÍDO")>0,"✔ SIM","—")
A11: Coesão e coerência textual; reescrita de frases | B11: NÃO | C11: NÃO | D11: NÃO | E11: =SUMIFS('Diário de estudo'!H3:H530,'Diário de estudo'!D3:D530,"LÍNGUA PORTUGUESA",'Diário de estudo'!F3:F530,A11) | F11: =SUMIFS('Diário de estudo'!I3:I530,'Diário de estudo'!D3:D530,"LÍNGUA PORTUGUESA",'Diário de estudo'!F3:F530,A11) | G11: =IFERROR(F11/E11,"") | L11: =IF(COUNTIFS('Diário de estudo'!$D$3:$D$530,"LÍNGUA PORTUGUESA",'Diário de estudo'!$F$3:$F$530,A11,'Diário de estudo'!$J$3:$J$530,"CONCLUÍDO")>0,"✔ SIM","—")
A12: Sintaxe (período simples e composto); concordância e regência | B12: NÃO | C12: NÃO | D12: NÃO | E12: =SUMIFS('Diário de estudo'!H3:H530,'Diário de estudo'!D3:D530,"LÍNGUA PORTUGUESA",'Diário de estudo'!F3:F530,A12) | F12: =SUMIFS('Diário de estudo'!I3:I530,'Diário de estudo'!D3:D530,"LÍNGUA PORTUGUESA",'Diário de estudo'!F3:F530,A12) | G12: =IFERROR(F12/E12,"") | L12: =IF(COUNTIFS('Diário de estudo'!$D$3:$D$530,"LÍNGUA PORTUGUESA",'Diário de estudo'!$F$3:$F$530,A12,'Diário de estudo'!$J$3:$J$530,"CONCLUÍDO")>0,"✔ SIM","—")
A13: Colocação pronominal, pontuação e variação linguística | B13: NÃO | C13: NÃO | D13: NÃO | E13: =SUMIFS('Diário de estudo'!H3:H530,'Diário de estudo'!D3:D530,"LÍNGUA PORTUGUESA",'Diário de estudo'!F3:F530,A13) | F13: =SUMIFS('Diário de estudo'!I3:I530,'Diário de estudo'!D3:D530,"LÍNGUA PORTUGUESA",'Diário de estudo'!F3:F530,A13) | G13: =IFERROR(F13/E13,"") | L13: =IF(COUNTIFS('Diário de estudo'!$D$3:$D$530,"LÍNGUA PORTUGUESA",'Diário de estudo'!$F$3:$F$530,A13,'Diário de estudo'!$J$3:$J$530,"CONCLUÍDO")>0,"✔ SIM","—")
A15: DIREITO CONSTITUCIONAL | K15: =IFERROR(COUNTIF(B16:B23,"SIM")/COUNTA(B16:B23),0) | L15: MATEI NO DIÁRIO?
B16: MATÉRIA ESTUDADA | C16: AULAS / TEORIA | D16: JÁ FIZ QUESTÕES? | E16: QTD. EXERC. | F16: ACERTOS | G16: DESEMP. (%) | H16: REVISÃO 1º | I16: REVISÃO 2º | J16: REVISÃO 3º | K16: ANOTAÇÕES
A17: Constitucionalismo, conceito e classificação das Constituições | B17: NÃO | C17: NÃO | D17: NÃO | E17: =SUMIFS('Diário de estudo'!H3:H530,'Diário de estudo'!D3:D530,"DIREITO CONSTITUCIONAL",'Diário de estudo'!F3:F530,A17) | F17: =SUMIFS('Diário de estudo'!I3:I530,'Diário de estudo'!D3:D530,"DIREITO CONSTITUCIONAL",'Diário de estudo'!F3:F530,A17) | G17: =IFERROR(F17/E17,"") | L17: =IF(COUNTIFS('Diário de estudo'!$D$3:$D$530,"DIREITO CONSTITUCIONAL",'Diário de estudo'!$F$3:$F$530,A17,'Diário de estudo'!$J$3:$J$530,"CONCLUÍDO")>0,"✔ SIM","—")
A18: Eficácia, aplicabilidade e interpretação das normas constitucionais | B18: NÃO | C18: NÃO | D18: NÃO | E18: =SUMIFS('Diário de estudo'!H3:H530,'Diário de estudo'!D3:D530,"DIREITO CONSTITUCIONAL",'Diário de estudo'!F3:F530,A18) | F18: =SUMIFS('Diário de estudo'!I3:I530,'Diário de estudo'!D3:D530,"DIREITO CONSTITUCIONAL",'Diário de estudo'!F3:F530,A18) | G18: =IFERROR(F18/E18,"") | L18: =IF(COUNTIFS('Diário de estudo'!$D$3:$D$530,"DIREITO CONSTITUCIONAL",'Diário de estudo'!$F$3:$F$530,A18,'Diário de estudo'!$J$3:$J$530,"CONCLUÍDO")>0,"✔ SIM","—")
A19: Poder Constituinte e Princípios Fundamentais | B19: NÃO | C19: NÃO | D19: NÃO | E19: =SUMIFS('Diário de estudo'!H3:H530,'Diário de estudo'!D3:D530,"DIREITO CONSTITUCIONAL",'Diário de estudo'!F3:F530,A19) | F19: =SUMIFS('Diário de estudo'!I3:I530,'Diário de estudo'!D3:D530,"DIREITO CONSTITUCIONAL",'Diário de estudo'!F3:F530,A19) | G19: =IFERROR(F19/E19,"") | L19: =IF(COUNTIFS('Diário de estudo'!$D$3:$D$530,"DIREITO CONSTITUCIONAL",'Diário de estudo'!$F$3:$F$530,A19,'Diário de estudo'!$J$3:$J$530,"CONCLUÍDO")>0,"✔ SIM","—")
A20: Direitos e Garantias Fundamentais | B20: NÃO | C20: NÃO | D20: NÃO | E20: =SUMIFS('Diário de estudo'!H3:H530,'Diário de estudo'!D3:D530,"DIREITO CONSTITUCIONAL",'Diário de estudo'!F3:F530,A20) | F20: =SUMIFS('Diário de estudo'!I3:I530,'Diário de estudo'!D3:D530,"DIREITO CONSTITUCIONAL",'Diário de estudo'!F3:F530,A20) | G20: =IFERROR(F20/E20,"") | L20: =IF(COUNTIFS('Diário de estudo'!$D$3:$D$530,"DIREITO CONSTITUCIONAL",'Diário de estudo'!$F$3:$F$530,A20,'Diário de estudo'!$J$3:$J$530,"CONCLUÍDO")>0,"✔ SIM","—")
A21: Organização do Estado e dos Poderes | B21: NÃO | C21: NÃO | D21: NÃO | E21: =SUMIFS('Diário de estudo'!H3:H530,'Diário de estudo'!D3:D530,"DIREITO CONSTITUCIONAL",'Diário de estudo'!F3:F530,A21) | F21: =SUMIFS('Diário de estudo'!I3:I530,'Diário de estudo'!D3:D530,"DIREITO CONSTITUCIONAL",'Diário de estudo'!F3:F530,A21) | G21: =IFERROR(F21/E21,"") | L21: =IF(COUNTIFS('Diário de estudo'!$D$3:$D$530,"DIREITO CONSTITUCIONAL",'Diário de estudo'!$F$3:$F$530,A21,'Diário de estudo'!$J$3:$J$530,"CONCLUÍDO")>0,"✔ SIM","—")
A22: Controle de Constitucionalidade | B22: NÃO | C22: NÃO | D22: NÃO | E22: =SUMIFS('Diário de estudo'!H3:H530,'Diário de estudo'!D3:D530,"DIREITO CONSTITUCIONAL",'Diário de estudo'!F3:F530,A22) | F22: =SUMIFS('Diário de estudo'!I3:I530,'Diário de estudo'!D3:D530,"DIREITO CONSTITUCIONAL",'Diário de estudo'!F3:F530,A22) | G22: =IFERROR(F22/E22,"") | L22: =IF(COUNTIFS('Diário de estudo'!$D$3:$D$530,"DIREITO CONSTITUCIONAL",'Diário de estudo'!$F$3:$F$530,A22,'Diário de estudo'!$J$3:$J$530,"CONCLUÍDO")>0,"✔ SIM","—")
A23: Administração Pública e Servidores Públicos (CF) | B23: NÃO | C23: NÃO | D23: NÃO | E23: =SUMIFS('Diário de estudo'!H3:H530,'Diário de estudo'!D3:D530,"DIREITO CONSTITUCIONAL",'Diário de estudo'!F3:F530,A23) | F23: =SUMIFS('Diário de estudo'!I3:I530,'Diário de estudo'!D3:D530,"DIREITO CONSTITUCIONAL",'Diário de estudo'!F3:F530,A23) | G23: =IFERROR(F23/E23,"") | L23: =IF(COUNTIFS('Diário de estudo'!$D$3:$D$530,"DIREITO CONSTITUCIONAL",'Diário de estudo'!$F$3:$F$530,A23,'Diário de estudo'!$J$3:$J$530,"CONCLUÍDO")>0,"✔ SIM","—")
A24: Tutelas constitucionais (HC, HD, MS, Ação Popular, ACP) | B24: NÃO | C24: NÃO | D24: NÃO | E24: =SUMIFS('Diário de estudo'!H3:H530,'Diário de estudo'!D3:D530,"DIREITO CONSTITUCIONAL",'Diário de estudo'!F3:F530,A24) | F24: =SUMIFS('Diário de estudo'!I3:I530,'Diário de estudo'!D3:D530,"DIREITO CONSTITUCIONAL",'Diário de estudo'!F3:F530,A24) | G24: =IFERROR(F24/E24,"") | L24: =IF(COUNTIFS('Diário de estudo'!$D$3:$D$530,"DIREITO CONSTITUCIONAL",'Diário de estudo'!$F$3:$F$530,A24,'Diário de estudo'!$J$3:$J$530,"CONCLUÍDO")>0,"✔ SIM","—")
A26: DIREITO ADMINISTRATIVO | K26: =IFERROR(COUNTIF(B27:B34,"SIM")/COUNTA(B27:B34),0) | L26: MATEI NO DIÁRIO?
B27: MATÉRIA ESTUDADA | C27: AULAS / TEORIA | D27: JÁ FIZ QUESTÕES? | E27: QTD. EXERC. | F27: ACERTOS | G27: DESEMP. (%) | H27: REVISÃO 1º | I27: REVISÃO 2º | J27: REVISÃO 3º | K27: ANOTAÇÕES
A28: Princípios e Poderes Administrativos | B28: NÃO | C28: NÃO | D28: NÃO | E28: =SUMIFS('Diário de estudo'!H3:H530,'Diário de estudo'!D3:D530,"DIREITO ADMINISTRATIVO",'Diário de estudo'!F3:F530,A28) | F28: =SUMIFS('Diário de estudo'!I3:I530,'Diário de estudo'!D3:D530,"DIREITO ADMINISTRATIVO",'Diário de estudo'!F3:F530,A28) | G28: =IFERROR(F28/E28,"") | L28: =IF(COUNTIFS('Diário de estudo'!$D$3:$D$530,"DIREITO ADMINISTRATIVO",'Diário de estudo'!$F$3:$F$530,A28,'Diário de estudo'!$J$3:$J$530,"CONCLUÍDO")>0,"✔ SIM","—")
A29: Organização Administrativa e Atos Administrativos | B29: NÃO | C29: NÃO | D29: NÃO | E29: =SUMIFS('Diário de estudo'!H3:H530,'Diário de estudo'!D3:D530,"DIREITO ADMINISTRATIVO",'Diário de estudo'!F3:F530,A29) | F29: =SUMIFS('Diário de estudo'!I3:I530,'Diário de estudo'!D3:D530,"DIREITO ADMINISTRATIVO",'Diário de estudo'!F3:F530,A29) | G29: =IFERROR(F29/E29,"") | L29: =IF(COUNTIFS('Diário de estudo'!$D$3:$D$530,"DIREITO ADMINISTRATIVO",'Diário de estudo'!$F$3:$F$530,A29,'Diário de estudo'!$J$3:$J$530,"CONCLUÍDO")>0,"✔ SIM","—")
A30: Responsabilidade Civil do Estado; Controle da Administração | B30: NÃO | C30: NÃO | D30: NÃO | E30: =SUMIFS('Diário de estudo'!H3:H530,'Diário de estudo'!D3:D530,"DIREITO ADMINISTRATIVO",'Diário de estudo'!F3:F530,A30) | F30: =SUMIFS('Diário de estudo'!I3:I530,'Diário de estudo'!D3:D530,"DIREITO ADMINISTRATIVO",'Diário de estudo'!F3:F530,A30) | G30: =IFERROR(F30/E30,"") | L30: =IF(COUNTIFS('Diário de estudo'!$D$3:$D$530,"DIREITO ADMINISTRATIVO",'Diário de estudo'!$F$3:$F$530,A30,'Diário de estudo'!$J$3:$J$530,"CONCLUÍDO")>0,"✔ SIM","—")
A31: Lei 8.666/93, Lei 14.133/2021 e Pregão (Lei 10.520/2002) | B31: NÃO | C31: NÃO | D31: NÃO | E31: =SUMIFS('Diário de estudo'!H3:H530,'Diário de estudo'!D3:D530,"DIREITO ADMINISTRATIVO",'Diário de estudo'!F3:F530,A31) | F31: =SUMIFS('Diário de estudo'!I3:I530,'Diário de estudo'!D3:D530,"DIREITO ADMINISTRATIVO",'Diário de estudo'!F3:F530,A31) | G31: =IFERROR(F31/E31,"") | L31: =IF(COUNTIFS('Diário de estudo'!$D$3:$D$530,"DIREITO ADMINISTRATIVO",'Diário de estudo'!$F$3:$F$530,A31,'Diário de estudo'!$J$3:$J$530,"CONCLUÍDO")>0,"✔ SIM","—")
A32: Serviços Públicos; Agentes Públicos e Concurso Público | B32: NÃO | C32: NÃO | D32: NÃO | E32: =SUMIFS('Diário de estudo'!H3:H530,'Diário de estudo'!D3:D530,"DIREITO ADMINISTRATIVO",'Diário de estudo'!F3:F530,A32) | F32: =SUMIFS('Diário de estudo'!I3:I530,'Diário de estudo'!D3:D530,"DIREITO ADMINISTRATIVO",'Diário de estudo'!F3:F530,A32) | G32: =IFERROR(F32/E32,"") | L32: =IF(COUNTIFS('Diário de estudo'!$D$3:$D$530,"DIREITO ADMINISTRATIVO",'Diário de estudo'!$F$3:$F$530,A32,'Diário de estudo'!$J$3:$J$530,"CONCLUÍDO")>0,"✔ SIM","—")
A33: Improbidade Administrativa | B33: NÃO | C33: NÃO | D33: NÃO | E33: =SUMIFS('Diário de estudo'!H3:H530,'Diário de estudo'!D3:D530,"DIREITO ADMINISTRATIVO",'Diário de estudo'!F3:F530,A33) | F33: =SUMIFS('Diário de estudo'!I3:I530,'Diário de estudo'!D3:D530,"DIREITO ADMINISTRATIVO",'Diário de estudo'!F3:F530,A33) | G33: =IFERROR(F33/E33,"") | L33: =IF(COUNTIFS('Diário de estudo'!$D$3:$D$530,"DIREITO ADMINISTRATIVO",'Diário de estudo'!$F$3:$F$530,A33,'Diário de estudo'!$J$3:$J$530,"CONCLUÍDO")>0,"✔ SIM","—")
A34: Processo Administrativo (Lei 9.784/99) e LAI (Lei 12.527/2011) | B34: NÃO | C34: NÃO | D34: NÃO | E34: =SUMIFS('Diário de estudo'!H3:H530,'Diário de estudo'!D3:D530,"DIREITO ADMINISTRATIVO",'Diário de estudo'!F3:F530,A34) | F34: =SUMIFS('Diário de estudo'!I3:I530,'Diário de estudo'!D3:D530,"DIREITO ADMINISTRATIVO",'Diário de estudo'!F3:F530,A34) | G34: =IFERROR(F34/E34,"") | L34: =IF(COUNTIFS('Diário de estudo'!$D$3:$D$530,"DIREITO ADMINISTRATIVO",'Diário de estudo'!$F$3:$F$530,A34,'Diário de estudo'!$J$3:$J$530,"CONCLUÍDO")>0,"✔ SIM","—")
A35: Lei de Responsabilidade Fiscal (LC 101/2000) | B35: NÃO | C35: NÃO | D35: NÃO | E35: =SUMIFS('Diário de estudo'!H3:H530,'Diário de estudo'!D3:D530,"DIREITO ADMINISTRATIVO",'Diário de estudo'!F3:F530,A35) | F35: =SUMIFS('Diário de estudo'!I3:I530,'Diário de estudo'!D3:D530,"DIREITO ADMINISTRATIVO",'Diário de estudo'!F3:F530,A35) | G35: =IFERROR(F35/E35,"") | L35: =IF(COUNTIFS('Diário de estudo'!$D$3:$D$530,"DIREITO ADMINISTRATIVO",'Diário de estudo'!$F$3:$F$530,A35,'Diário de estudo'!$J$3:$J$530,"CONCLUÍDO")>0,"✔ SIM","—")
A37: LEGISLAÇÃO INSTITUCIONAL MP | K37: =IFERROR(COUNTIF(B38:B42,"SIM")/COUNTA(B38:B42),0) | L37: MATEI NO DIÁRIO?
B38: MATÉRIA ESTUDADA | C38: AULAS / TEORIA | D38: JÁ FIZ QUESTÕES? | E38: QTD. EXERC. | F38: ACERTOS | G38: DESEMP. (%) | H38: REVISÃO 1º | I38: REVISÃO 2º | J38: REVISÃO 3º | K38: ANOTAÇÕES
A39: Lei Orgânica Nacional do MP (Lei 8.625/93) | B39: NÃO | C39: NÃO | D39: NÃO | E39: =SUMIFS('Diário de estudo'!H3:H530,'Diário de estudo'!D3:D530,"LEGISLAÇÃO INSTITUCIONAL MP",'Diário de estudo'!F3:F530,A39) | F39: =SUMIFS('Diário de estudo'!I3:I530,'Diário de estudo'!D3:D530,"LEGISLAÇÃO INSTITUCIONAL MP",'Diário de estudo'!F3:F530,A39) | G39: =IFERROR(F39/E39,"") | L39: =IF(COUNTIFS('Diário de estudo'!$D$3:$D$530,"LEGISLAÇÃO INSTITUCIONAL MP",'Diário de estudo'!$F$3:$F$530,A39,'Diário de estudo'!$J$3:$J$530,"CONCLUÍDO")>0,"✔ SIM","—")
A40: Lei Orgânica do MPMS (LC Estadual 72/1994) | B40: NÃO | C40: NÃO | D40: NÃO | E40: =SUMIFS('Diário de estudo'!H3:H530,'Diário de estudo'!D3:D530,"LEGISLAÇÃO INSTITUCIONAL MP",'Diário de estudo'!F3:F530,A40) | F40: =SUMIFS('Diário de estudo'!I3:I530,'Diário de estudo'!D3:D530,"LEGISLAÇÃO INSTITUCIONAL MP",'Diário de estudo'!F3:F530,A40) | G40: =IFERROR(F40/E40,"") | L40: =IF(COUNTIFS('Diário de estudo'!$D$3:$D$530,"LEGISLAÇÃO INSTITUCIONAL MP",'Diário de estudo'!$F$3:$F$530,A40,'Diário de estudo'!$J$3:$J$530,"CONCLUÍDO")>0,"✔ SIM","—")
A41: Estatuto dos Funcionários Públicos do MS (Lei 1.102/1990) | B41: NÃO | C41: NÃO | D41: NÃO | E41: =SUMIFS('Diário de estudo'!H3:H530,'Diário de estudo'!D3:D530,"LEGISLAÇÃO INSTITUCIONAL MP",'Diário de estudo'!F3:F530,A41) | F41: =SUMIFS('Diário de estudo'!I3:I530,'Diário de estudo'!D3:D530,"LEGISLAÇÃO INSTITUCIONAL MP",'Diário de estudo'!F3:F530,A41) | G41: =IFERROR(F41/E41,"") | L41: =IF(COUNTIFS('Diário de estudo'!$D$3:$D$530,"LEGISLAÇÃO INSTITUCIONAL MP",'Diário de estudo'!$F$3:$F$530,A41,'Diário de estudo'!$J$3:$J$530,"CONCLUÍDO")>0,"✔ SIM","—")
A42: Plano de Cargos/Carreiras MPMS (Lei 4.134/2011) + LGPD (Lei 13.709/2018) | B42: NÃO | C42: NÃO | D42: NÃO | E42: =SUMIFS('Diário de estudo'!H3:H530,'Diário de estudo'!D3:D530,"LEGISLAÇÃO INSTITUCIONAL MP",'Diário de estudo'!F3:F530,A42) | F42: =SUMIFS('Diário de estudo'!I3:I530,'Diário de estudo'!D3:D530,"LEGISLAÇÃO INSTITUCIONAL MP",'Diário de estudo'!F3:F530,A42) | G42: =IFERROR(F42/E42,"") | L42: =IF(COUNTIFS('Diário de estudo'!$D$3:$D$530,"LEGISLAÇÃO INSTITUCIONAL MP",'Diário de estudo'!$F$3:$F$530,A42,'Diário de estudo'!$J$3:$J$530,"CONCLUÍDO")>0,"✔ SIM","—")
A43: Política Antifraude e Código de Ética do MPMS | B43: NÃO | C43: NÃO | D43: NÃO | E43: =SUMIFS('Diário de estudo'!H3:H530,'Diário de estudo'!D3:D530,"LEGISLAÇÃO INSTITUCIONAL MP",'Diário de estudo'!F3:F530,A43) | F43: =SUMIFS('Diário de estudo'!I3:I530,'Diário de estudo'!D3:D530,"LEGISLAÇÃO INSTITUCIONAL MP",'Diário de estudo'!F3:F530,A43) | G43: =IFERROR(F43/E43,"") | L43: =IF(COUNTIFS('Diário de estudo'!$D$3:$D$530,"LEGISLAÇÃO INSTITUCIONAL MP",'Diário de estudo'!$F$3:$F$530,A43,'Diário de estudo'!$J$3:$J$530,"CONCLUÍDO")>0,"✔ SIM","—")
A45: ENGENHARIA DE SOFTWARE | K45: =IFERROR(COUNTIF(B46:B51,"SIM")/COUNTA(B46:B51),0) | L45: MATEI NO DIÁRIO?
B46: MATÉRIA ESTUDADA | C46: AULAS / TEORIA | D46: JÁ FIZ QUESTÕES? | E46: QTD. EXERC. | F46: ACERTOS | G46: DESEMP. (%) | H46: REVISÃO 1º | I46: REVISÃO 2º | J46: REVISÃO 3º | K46: ANOTAÇÕES
...

Sheet CONTROLE DE QUESTÕES
A1: CONTROLE DE QUESTÕES POR SEMANA — somado automaticamente do Diário de estudo
A2: MATÉRIA | B2: SEMANA 1 14/09 | E2: SEMANA 2 21/09 | H2: SEMANA 3 28/09 | K2: SEMANA 4 05/10 | N2: SEMANA 5 12/10 | Q2: SEMANA 6 19/10 | T2: SEMANA 7 26/10 | W2: SEMANA 8 02/11 | Z2: SEMANA 9 09/11 | AC2: SEMANA 10 16/11 | AF2: SEMANA 11 23/11 | AI2: SEMANA 12 30/11 | AL2: SEMANA 13 07/12 | AO2: SEMANA 14 14/12 | AR2: SEMANA 15 21/12 | AU2: SEMANA 16 28/12
B3: Nº QUESTÕES | C3: ACERTOS | D3: DESEMP. % | E3: Nº QUESTÕES | F3: ACERTOS | G3: DESEMP. % | H3: Nº QUESTÕES | I3: ACERTOS | J3: DESEMP. % | K3: Nº QUESTÕES | L3: ACERTOS | M3: DESEMP. % | N3: Nº QUESTÕES | O3: ACERTOS | P3: DESEMP. % | Q3: Nº QUESTÕES | R3: ACERTOS | S3: DESEMP. % | T3: Nº QUESTÕES | U3: ACERTOS | V3: DESEMP. % | W3: Nº QUESTÕES | X3: ACERTOS | Y3: DESEMP. % | Z3: Nº QUESTÕES | AA3: ACERTOS | AB3: DESEMP. % | AC3: Nº QUESTÕES | AD3: ACERTOS | AE3: DESEMP. % | AF3: Nº QUESTÕES | AG3: ACERTOS | AH3: DESEMP. % | AI3: Nº QUESTÕES | AJ3: ACERTOS | AK3: DESEMP. % | AL3: Nº QUESTÕES | AM3: ACERTOS | AN3: DESEMP. % | AO3: Nº QUESTÕES | AP3: ACERTOS | AQ3: DESEMP. % | AR3: Nº QUESTÕES | AS3: ACERTOS | AT3: DESEMP. % | AU3: Nº QUESTÕES | AV3: ACERTOS | AW3: DESEMP. %
A4: LÍNGUA PORTUGUESA | B4: =SUMIFS('Diário de estudo'!H3:H530,'Diário de estudo'!D3:D530,$A4,'Diário de estudo'!A3:A530,">="&DATE(2026,9,14),'Diário de estudo'!A3:A530,"<="&DATE(2026,9,20)) | C4: =SUMIFS('Diário de estudo'!I3:I530,'Diário de estudo'!D3:D530,$A4,'Diário de estudo'!A3:A530,">="&DATE(2026,9,14),'Diário de estudo'!A3:A530,"<="&DATE(2026,9,20)) | D4: =IFERROR(C4/B4,"") | E4: =SUMIFS('Diário de estudo'!H3:H530,'Diário de estudo'!D3:D530,$A4,'Diário de estudo'!A3:A530,">="&DATE(2026,9,21),'Diário de estudo'!A3:A530,"<="&DATE(2026,9,27)) | F4: =SUMIFS('Diário de estudo'!I3:I530,'Diário de estudo'!D3:D530,$A4,'Diário de estudo'!A3:A530,">="&DATE(2026,9,21),'Diário de estudo'!A3:A530,"<="&DATE(2026,9,27)) | G4: =IFERROR(F4/E4,"") | H4: =SUMIFS('Diário de estudo'!H3:H530,'Diário de estudo'!D3:D530,$A4,'Diário de estudo'!A3:A530,">="&DATE(2026,9,28),'Diário de estudo'!A3:A530,"<="&DATE(2026,10,4)) | I4: =SUMIFS('Diário de estudo'!I3:I530,'Diário de estudo'!D3:D530,$A4,'Diário de estudo'!A3:A530,">="&DATE(2026,9,28),'Diário de estudo'!A3:A530,"<="&DATE(2026,10,4)) | J4: =IFERROR(I4/H4,"") | K4: =SUMIFS('Diário de estudo'!H3:H530,'Diário de estudo'!D3:D530,$A4,'Diário de estudo'!A3:A530,">="&DATE(2026,10,5),'Diário de estudo'!A3:A530,"<="&DATE(2026,10,11)) | L4: =SUMIFS('Diário de estudo'!I3:I530,'Diário de estudo'!D3:D530,$A4,'Diário de estudo'!A3:A530,">="&DATE(2026,10,5),'Diário de estudo'!A3:A530,"<="&DATE(2026,10,11)) | M4: =IFERROR(L4/K4,"") | N4: =SUMIFS('Diário de estudo'!H3:H530,'Diário de estudo'!D3:D530,$A4,'Diário de estudo'!A3:A530,">="&DATE(2026,10,12),'Diário de estudo'!A3:A530,"<="&DATE(2026,10,18)) | O4: =SUMIFS('Diário de estudo'!I3:I530,'Diário de estudo'!D3:D530,$A4,'Diário de estudo'!A3:A530,">="&DATE(2026,10,12),'Diário de estudo'!A3:A530,"<="&DATE(2026,10,18)) | P4: =IFERROR(O4/N4,"") | Q4: =SUMIFS('Diário de estudo'!H3:H530,'Diário de estudo'!D3:D530,$A4,'Diário de estudo'!A3:A530,">="&DATE(2026,10,19),'Diário de estudo'!A3:A530,"<="&DATE(2026,10,25)) | R4: =SUMIFS('Diário de estudo'!I3:I530,'Diário de estudo'!D3:D530,$A4,'Diário de estudo'!A3:A530,">="&DATE(2026,10,19),'Diário de estudo'!A3:A530,"<="&DATE(2026,10,25)) | S4: =IFERROR(R4/Q4,"") | T4: =SUMIFS('Diário de estudo'!H3:H530,'Diário de estudo'!D3:D530,$A4,'Diário de estudo'!A3:A530,">="&DATE(2026,10,26),'Diário de estudo'!A3:A530,"<="&DATE(2026,11,1)) | U4: =SUMIFS('Diário de estudo'!I3:I530,'Diário de estudo'!D3:D530,$A4,'Diário de estudo'!A3:A530,">="&DATE(2026,10,26),'Diário de estudo'!A3:A530,"<="&DATE(2026,11,1)) | V4: =IFERROR(U4/T4,"") | W4: =SUMIFS('Diário de estudo'!H3:H530,'Diário de estudo'!D3:D530,$A4,'Diário de estudo'!A3:A530,">="&DATE(2026,11,2),'Diário de estudo'!A3:A530,"<="&DATE(2026,11,8)) | X4: =SUMIFS('Diário de estudo'!I3:I530,'Diário de estudo'!D3:D530,$A4,'Diário de estudo'!A3:A530,">="&DATE(2026,11,2),'Diário de estudo'!A3:A530,"<="&DATE(2026,11,8)) | Y4: =IFERROR(X4/W4,"") | Z4: =SUMIFS('Diário de estudo'!H3:H530,'Diário de estudo'!D3:D530,$A4,'Diário de estudo'!A3:A530,">="&DATE(2026,11,9),'Diário de estudo'!A3:A530,"<="&DATE(2026,11,15)) | AA4: =SUMIFS('Diário de estudo'!I3:I530,'Diário de estudo'!D3:D530,$A4,'Diário de estudo'!A3:A530,">="&DATE(2026,11,9),'Diário de estudo'!A3:A530,"<="&DATE(2026,11,15)) | AB4: =IFERROR(AA4/Z4,"") | AC4: =SUMIFS('Diário de estudo'!H3:H530,'Diário de estudo'!D3:D530,$A4,'Diário de estudo'!A3:A530,">="&DATE(2026,11,16),'Diário de estudo'!A3:A530,"<="&DATE(2026,11,22)) | AD4: =SUMIFS('Diário de estudo'!I3:I530,'Diário de estudo'!D3:D530,$A4,'Diário de estudo'!A3:A530,">="&DATE(2026,11,16),'Diário de estudo'!A3:A530,"<="&DATE(2026,11,22)) | AE4: =IFERROR(AD4/AC4,"") | AF4: =SUMIFS('Diário de estudo'!H3:H530,'Diário de estudo'!D3:D530,$A4,'Diário de estudo'!A3:A530,">="&DATE(2026,11,23),'Diário de estudo'!A3:A530,"<="&DATE(2026,11,29)) | AG4: =SUMIFS('Diário de estudo'!I3:I530,'Diário de estudo'!D3:D530,$A4,'Diário de estudo'!A3:A530,">="&DATE(2026,11,23),'Diário de estudo'!A3:A530,"<="&DATE(2026,11,29)) | AH4: =IFERROR(AG4/AF4,"") | AI4: =SUMIFS('Diário de estudo'!H3:H530,'Diário de estudo'!D3:D530,$A4,'Diário de estudo'!A3:A530,">="&DATE(2026,11,30),'Diário de estudo'!A3:A530,"<="&DATE(2026,12,6)) | AJ4: =SUMIFS('Diário de estudo'!I3:I530,'Diário de estudo'!D3:D530,$A4,'Diário de estudo'!A3:A530,">="&DATE(2026,11,30),'Diário de estudo'!A3:A530,"<="&DATE(2026,12,6)) | AK4: =IFERROR(AJ4/AI4,"") | AL4: =SUMIFS('Diário de estudo'!H3:H530,'Diário de estudo'!D3:D530,$A4,'Diário de estudo'!A3:A530,">="&DATE(2026,12,7),'Diário de estudo'!A3:A530,"<="&DATE(2026,12,13)) | AM4: =SUMIFS('Diário de estudo'!I3:I530,'Diário de estudo'!D3:D530,$A4,'Diário de estudo'!A3:A530,">="&DATE(2026,12,7),'Diário de estudo'!A3:A530,"<="&DATE(2026,12,13)) | AN4: =IFERROR(AM4/AL4,"") | AO4: =SUMIFS('Diário de estudo'!H3:H530,'Diário de estudo'!D3:D530,$A4,'Diário de estudo'!A3:A530,">="&DATE(2026,12,14),'Diário de estudo'!A3:A530,"<="&DATE(2026,12,20)) | AP4: =SUMIFS('Diário de estudo'!I3:I530,'Diário de estudo'!D3:D530,$A4,'Diário de estudo'!A3:A530,">="&DATE(2026,12,14),'Diário de estudo'!A3:A530,"<="&DATE(2026,12,20)) | AQ4: =IFERROR(AP4/AO4,"") | AR4: =SUMIFS('Diário de estudo'!H3:H530,'Diário de estudo'!D3:D530,$A4,'Diário de estudo'!A3:A530,">="&DATE(2026,12,21),'Diário de estudo'!A3:A530,"<="&DATE(2026,12,27)) | AS4: =SUMIFS('Diário de estudo'!I3:I530,'Diário de estudo'!D3:D530,$A4,'Diário de estudo'!A3:A530,">="&DATE(2026,12,21),'Diário de estudo'!A3:A530,"<="&DATE(2026,12,27)) | AT4: =IFERROR(AS4/AR4,"") | AU4: =SUMIFS('Diário de estudo'!H3:H530,'Diário de estudo'!D3:D530,$A4,'Diário de estudo'!A3:A530,">="&DATE(2026,12,28),'Diário de estudo'!A3:A530,"<="&DATE(2027,1,3)) | AV4: =SUMIFS('Diário de estudo'!I3:I530,'Diário de estudo'!D3:D530,$A4,'Diário de estudo'!A3:A530,">="&DATE(2026,12,28),'Diário de estudo'!A3:A530,"<="&DATE(2027,1,3)) | AW4: =IFERROR(AV4/AU4,"")
A5: DIREITO CONSTITUCIONAL | B5: =SUMIFS('Diário de estudo'!H3:H530,'Diário de estudo'!D3:D530,$A5,'Diário de estudo'!A3:A530,">="&DATE(2026,9,14),'Diário de estudo'!A3:A530,"<="&DATE(2026,9,20)) | C5: =SUMIFS('Diário de estudo'!I3:I530,'Diário de estudo'!D3:D530,$A5,'Diário de estudo'!A3:A530,">="&DATE(2026,9,14),'Diário de estudo'!A3:A530,"<="&DATE(2026,9,20)) | D5: =IFERROR(C5/B5,"") | E5: =SUMIFS('Diário de estudo'!H3:H530,'Diário de estudo'!D3:D530,$A5,'Diário de estudo'!A3:A530,">="&DATE(2026,9,21),'Diário de estudo'!A3:A530,"<="&DATE(2026,9,27)) | F5: =SUMIFS('Diário de estudo'!I3:I530,'Diário de estudo'!D3:D530,$A5,'Diário de estudo'!A3:A530,">="&DATE(2026,9,21),'Diário de estudo'!A3:A530,"<="&DATE(2026,9,27)) | G5: =IFERROR(F5/E5,"") | H5: =SUMIFS('Diário de estudo'!H3:H530,'Diário de estudo'!D3:D530,$A5,'Diário de estudo'!A3:A530,">="&DATE(2026,9,28),'Diário de estudo'!A3:A530,"<="&DATE(2026,10,4)) | I5: =SUMIFS('Diário de estudo'!I3:I530,'Diário de estudo'!D3:D530,$A5,'Diário de estudo'!A3:A530,">="&DATE(2026,9,28),'Diário de estudo'!A3:A530,"<="&DATE(2026,10,4)) | J5: =IFERROR(I5/H5,"") | K5: =SUMIFS('Diário de estudo'!H3:H530,'Diário de estudo'!D3:D530,$A5,'Diário de estudo'!A3:A530,">="&DATE(2026,10,5),'Diário de estudo'!A3:A530,"<="&DATE(2026,10,11)) | L5: =SUMIFS('Diário de estudo'!I3:I530,'Diário de estudo'!D3:D530,$A5,'Diário de estudo'!A3:A530,">="&DATE(2026,10,5),'Diário de estudo'!A3:A530,"<="&DATE(2026,10,11)) | M5: =IFERROR(L5/K5,"") | N5: =SUMIFS('Diário de estudo'!H3:H530,'Diário de estudo'!D3:D530,$A5,'Diário de estudo'!A3:A530,">="&DATE(2026,10,12),'Diário de estudo'!A3:A530,"<="&DATE(2026,10,18)) | O5: =SUMIFS('Diário de estudo'!I3:I530,'Diário de estudo'!D3:D530,$A5,'Diário de estudo'!A3:A530,">="&DATE(2026,10,12),'Diário de estudo'!A3:A530,"<="&DATE(2026,10,18)) | P5: =IFERROR(O5/N5,"") | Q5: =SUMIFS('Diário de estudo'!H3:H530,'Diário de estudo'!D3:D530,$A5,'Diário de estudo'!A3:A530,">="&DATE(2026,10,19),'Diário de estudo'!A3:A530,"<="&DATE(2026,10,25)) | R5: =SUMIFS('Diário de estudo'!I3:I530,'Diário de estudo'!D3:D530,$A5,'Diário de estudo'!A3:A530,">="&DATE(2026,10,19),'Diário de estudo'!A3:A530,"<="&DATE(2026,10,25)) | S5: =IFERROR(R5/Q5,"") | T5: =SUMIFS('Diário de estudo'!H3:H530,'Diário de estudo'!D3:D530,$A5,'Diário de estudo'!A3:A530,">="&DATE(2026,10,26),'Diário de estudo'!A3:A530,"<="&DATE(2026,11,1)) | U5: =SUMIFS('Diário de estudo'!I3:I530,'Diário de estudo'!D3:D530,$A5,'Diário de estudo'!A3:A530,">="&DATE(2026,10,26),'Diário de estudo'!A3:A530,"<="&DATE(2026,11,1)) | V5: =IFERROR(U5/T5,"") | W5: =SUMIFS('Diário de estudo'!H3:H530,'Diário de estudo'!D3:D530,$A5,'Diário de estudo'!A3:A530,">="&DATE(2026,11,2),'Diário de estudo'!A3:A530,"<="&DATE(2026,11,8)) | X5: =SUMIFS('Diário de estudo'!I3:I530,'Diário de estudo'!D3:D530,$A5,'Diário de estudo'!A3:A530,">="&DATE(2026,11,2),'Diário de estudo'!A3:A530,"<="&DATE(2026,11,8)) | Y5: =IFERROR(X5/W5,"") | Z5: =SUMIFS('Diário de estudo'!H3:H530,'Diário de estudo'!D3:D530,$A5,'Diário de estudo'!A3:A530,">="&DATE(2026,11,9),'Diário de estudo'!A3:A530,"<="&DATE(2026,11,15)) | AA5: =SUMIFS('Diário de estudo'!I3:I530,'Diário de estudo'!D3:D530,$A5,'Diário de estudo'!A3:A530,">="&DATE(2026,11,9),'Diário de estudo'!A3:A530,"<="&DATE(2026,11,15)) | AB5: =IFERROR(AA5/Z5,"") | AC5: =SUMIFS('Diário de estudo'!H3:H530,'Diário de estudo'!D3:D530,$A5,'Diário de estudo'!A3:A530,">="&DATE(2026,11,16),'Diário de estudo'!A3:A530,"<="&DATE(2026,11,22)) | AD5: =SUMIFS('Diário de estudo'!I3:I530,'Diário de estudo'!D3:D530,$A5,'Diário de estudo'!A3:A530,">="&DATE(2026,11,16),'Diário de estudo'!A3:A530,"<="&DATE(2026,11,22)) | AE5: =IFERROR(AD5/AC5,"") | AF5: =SUMIFS('Diário de estudo'!H3:H530,'Diário de estudo'!D3:D530,$A5,'Diário de estudo'!A3:A530,">="&DATE(2026,11,23),'Diário de estudo'!A3:A530,"<="&DATE(2026,11,29)) | AG5: =SUMIFS('Diário de estudo'!I3:I530,'Diário de estudo'!D3:D530,$A5,'Diário de estudo'!A3:A530,">="&DATE(2026,11,23),'Diário de estudo'!A3:A530,"<="&DATE(2026,11,29)) | AH5: =IFERROR(AG5/AF5,"") | AI5: =SUMIFS('Diário de estudo'!H3:H530,'Diário de estudo'!D3:D530,$A5,'Diário de estudo'!A3:A530,">="&DATE(2026,11,30),'Diário de estudo'!A3:A530,"<="&DATE(2026,12,6)) | AJ5: =SUMIFS('Diário de estudo'!I3:I530,'Diário de estudo'!D3:D530,$A5,'Diário de estudo'!A3:A530,">="&DATE(2026,11,30),'Diário de estudo'!A3:A530,"<="&DATE(2026,12,6)) | AK5: =IFERROR(AJ5/AI5,"") | AL5: =SUMIFS('Diário de estudo'!H3:H530,'Diário de estudo'!D3:D530,$A5,'Diário de estudo'!A3:A530,">="&DATE(2026,12,7),'Diário de estudo'!A3:A530,"<="&DATE(2026,12,13)) | AM5: =SUMIFS('Diário de estudo'!I3:I530,'Diário de estudo'!D3:D530,$A5,'Diário de estudo'!A3:A530,">="&DATE(2026,12,7),'Diário de estudo'!A3:A530,"<="&DATE(2026,12,13)) | AN5: =IFERROR(AM5/AL5,"") | AO5: =SUMIFS('Diário de estudo'!H3:H530,'Diário de estudo'!D3:D530,$A5,'Diário de estudo'!A3:A530,">="&DATE(2026,12,14),'Diário de estudo'!A3:A530,"<="&DATE(2026,12,20)) | AP5: =SUMIFS('Diário de estudo'!I3:I530,'Diário de estudo'!D3:D530,$A5,'Diário de estudo'!A3:A530,">="&DATE(2026,12,14),'Diário de estudo'!A3:A530,"<="&DATE(2026,12,20)) | AQ5: =IFERROR(AP5/AO5,"") | AR5: =SUMIFS('Diário de estudo'!H3:H530,'Diário de estudo'!D3:D530,$A5,'Diário de estudo'!A3:A530,">="&DATE(2026,12,21),'Diário de estudo'!A3:A530,"<="&DATE(2026,12,27)) | AS5: =SUMIFS('Diário de estudo'!I3:I530,'Diário de estudo'!D3:D530,$A5,'Diário de estudo'!A3:A530,">="&DATE(2026,12,21),'Diário de estudo'!A3:A530,"<="&DATE(2026,12,27)) | AT5: =IFERROR(AS5/AR5,"") | AU5: =SUMIFS('Diário de estudo'!H3:H530,'Diário de estudo'!D3:D530,$A5,'Diário de estudo'!A3:A530,">="&DATE(2026,12,28),'Diário de estudo'!A3:A530,"<="&DATE(2027,1,3)) | AV5: =SUMIFS('Diário de estudo'!I3:I530,'Diário de estudo'!D3:D530,$A5,'Diário de estudo'!A3:A530,">="&DATE(2026,12,28),'Diário de estudo'!A3:A530,"<="&DATE(2027,1,3)) | AW5: =IFERROR(AV5/AU5,"")
A6: DIREITO ADMINISTRATIVO | B6: =SUMIFS('Diário de estudo'!H3:H530,'Diário de estudo'!D3:D530,$A6,'Diário de estudo'!A3:A530,">="&DATE(2026,9,14),'Diário de estudo'!A3:A530,"<="&DATE(2026,9,20)) | C6: =SUMIFS('Diário de estudo'!I3:I530,'Diário de estudo'!D3:D530,$A6,'Diário de estudo'!A3:A530,">="&DATE(2026,9,14),'Diário de estudo'!A3:A530,"<="&DATE(2026,9,20)) | D6: =IFERROR(C6/B6,"") | E6: =SUMIFS('Diário de estudo'!H3:H530,'Diário de estudo'!D3:D530,$A6,'Diário de estudo'!A3:A530,">="&DATE(2026,9,21),'Diário de estudo'!A3:A530,"<="&DATE(2026,9,27)) | F6: =SUMIFS('Diário de estudo'!I3:I530,'Diário de estudo'!D3:D530,$A6,'Diário de estudo'!A3:A530,">="&DATE(2026,9,21),'Diário de estudo'!A3:A530,"<="&DATE(2026,9,27)) | G6: =IFERROR(F6/E6,"") | H6: =SUMIFS('Diário de estudo'!H3:H530,'Diário de estudo'!D3:D530,$A6,'Diário de estudo'!A3:A530,">="&DATE(2026,9,28),'Diário de estudo'!A3:A530,"<="&DATE(2026,10,4)) | I6: =SUMIFS('Diário de estudo'!I3:I530,'Diário de estudo'!D3:D530,$A6,'Diário de estudo'!A3:A530,">="&DATE(2026,9,28),'Diário de estudo'!A3:A530,"<="&DATE(2026,10,4)) | J6: =IFERROR(I6/H6,"") | K6: =SUMIFS('Diário de estudo'!H3:H530,'Diário de estudo'!D3:D530,$A6,'Diário de estudo'!A3:A530,">="&DATE(2026,10,5),'Diário de estudo'!A3:A530,"<="&DATE(2026,10,11)) | L6: =SUMIFS('Diário de estudo'!I3:I530,'Diário de estudo'!D3:D530,$A6,'Diário de estudo'!A3:A530,">="&DATE(2026,10,5),'Diário de estudo'!A3:A530,"<="&DATE(2026,10,11)) | M6: =IFERROR(L6/K6,"") | N6: =SUMIFS('Diário de estudo'!H3:H530,'Diário de estudo'!D3:D530,$A6,'Diário de estudo'!A3:A530,">="&DATE(2026,10,12),'Diário de estudo'!A3:A530,"<="&DATE(2026,10,18)) | O6: =SUMIFS('Diário de estudo'!I3:I530,'Diário de estudo'!D3:D530,$A6,'Diário de estudo'!A3:A530,">="&DATE(2026,10,12),'Diário de estudo'!A3:A530,"<="&DATE(2026,10,18)) | P6: =IFERROR(O6/N6,"") | Q6: =SUMIFS('Diário de estudo'!H3:H530,'Diário de estudo'!D3:D530,$A6,'Diário de estudo'!A3:A530,">="&DATE(2026,10,19),'Diário de estudo'!A3:A530,"<="&DATE(2026,10,25)) | R6: =SUMIFS('Diário de estudo'!I3:I530,'Diário de estudo'!D3:D530,$A6,'Diário de estudo'!A3:A530,">="&DATE(2026,10,19),'Diário de estudo'!A3:A530,"<="&DATE(2026,10,25)) | S6: =IFERROR(R6/Q6,"") | T6: =SUMIFS('Diário de estudo'!H3:H530,'Diário de estudo'!D3:D530,$A6,'Diário de estudo'!A3:A530,">="&DATE(2026,10,26),'Diário de estudo'!A3:A530,"<="&DATE(2026,11,1)) | U6: =SUMIFS('Diário de estudo'!I3:I530,'Diário de estudo'!D3:D530,$A6,'Diário de estudo'!A3:A530,">="&DATE(2026,10,26),'Diário de estudo'!A3:A530,"<="&DATE(2026,11,1)) | V6: =IFERROR(U6/T6,"") | W6: =SUMIFS('Diário de estudo'!H3:H530,'Diário de estudo'!D3:D530,$A6,'Diário de estudo'!A3:A530,">="&DATE(2026,11,2),'Diário de estudo'!A3:A530,"<="&DATE(2026,11,8)) | X6: =SUMIFS('Diário de estudo'!I3:I530,'Diário de estudo'!D3:D530,$A6,'Diário de estudo'!A3:A530,">="&DATE(2026,11,2),'Diário de estudo'!A3:A530,"<="&DATE(2026,11,8)) | Y6: =IFERROR(X6/W6,"") | Z6: =SUMIFS('Diário de estudo'!H3:H530,'Diário de estudo'!D3:D530,$A6,'Diário de estudo'!A3:A530,">="&DATE(2026,11,9),'Diário de estudo'!A3:A530,"<="&DATE(2026,11,15)) | AA6: =SUMIFS('Diário de estudo'!I3:I530,'Diário de estudo'!D3:D530,$A6,'Diário de estudo'!A3:A530,">="&DATE(2026,11,9),'Diário de estudo'!A3:A530,"<="&DATE(2026,11,15)) | AB6: =IFERROR(AA6/Z6,"") | AC6: =SUMIFS('Diário de estudo'!H3:H530,'Diário de estudo'!D3:D530,$A6,'Diário de estudo'!A3:A530,">="&DATE(2026,11,16),'Diário de estudo'!A3:A530,"<="&DATE(2026,11,22)) | AD6: =SUMIFS('Diário de estudo'!I3:I530,'Diário de estudo'!D3:D530,$A6,'Diário de estudo'!A3:A530,">="&DATE(2026,11,16),'Diário de estudo'!A3:A530,"<="&DATE(2026,11,22)) | AE6: =IFERROR(AD6/AC6,"") | AF6: =SUMIFS('Diário de estudo'!H3:H530,'Diário de estudo'!D3:D530,$A6,'Diário de estudo'!A3:A530,">="&DATE(2026,11,23),'Diário de estudo'!A3:A530,"<="&DATE(2026,11,29)) | AG6: =SUMIFS('Diário de estudo'!I3:I530,'Diário de estudo'!D3:D530,$A6,'Diário de estudo'!A3:A530,">="&DATE(2026,11,23),'Diário de estudo'!A3:A530,"<="&DATE(2026,11,29)) | AH6: =IFERROR(AG6/AF6,"") | AI6: =SUMIFS('Diário de estudo'!H3:H530,'Diário de estudo'!D3:D530,$A6,'Diário de estudo'!A3:A530,">="&DATE(2026,11,30),'Diário de estudo'!A3:A530,"<="&DATE(2026,12,6)) | AJ6: =SUMIFS('Diário de estudo'!I3:I530,'Diário de estudo'!D3:D530,$A6,'Diário de estudo'!A3:A530,">="&DATE(2026,11,30),'Diário de estudo'!A3:A530,"<="&DATE(2026,12,6)) | AK6: =IFERROR(AJ6/AI6,"") | AL6: =SUMIFS('Diário de estudo'!H3:H530,'Diário de estudo'!D3:D530,$A6,'Diário de estudo'!A3:A530,">="&DATE(2026,12,7),'Diário de estudo'!A3:A530,"<="&DATE(2026,12,13)) | AM6: =SUMIFS('Diário de estudo'!I3:I530,'Diário de estudo'!D3:D530,$A6,'Diário de estudo'!A3:A530,">="&DATE(2026,12,7),'Diário de estudo'!A3:A530,"<="&DATE(2026,12,13)) | AN6: =IFERROR(AM6/AL6,"") | AO6: =SUMIFS('Diário de estudo'!H3:H530,'Diário de estudo'!D3:D530,$A6,'Diário de estudo'!A3:A530,">="&DATE(2026,12,14),'Diário de estudo'!A3:A530,"<="&DATE(2026,12,20)) | AP6: =SUMIFS('Diário de estudo'!I3:I530,'Diário de estudo'!D3:D530,$A6,'Diário de estudo'!A3:A530,">="&DATE(2026,12,14),'Diário de estudo'!A3:A530,"<="&DATE(2026,12,20)) | AQ6: =IFERROR(AP6/AO6,"") | AR6: =SUMIFS('Diário de estudo'!H3:H530,'Diário de estudo'!D3:D530,$A6,'Diário de estudo'!A3:A530,">="&DATE(2026,12,21),'Diário de estudo'!A3:A530,"<="&DATE(2026,12,27)) | AS6: =SUMIFS('Diário de estudo'!I3:I530,'Diário de estudo'!D3:D530,$A6,'Diário de estudo'!A3:A530,">="&DATE(2026,12,21),'Diário de estudo'!A3:A530,"<="&DATE(2026,12,27)) | AT6: =IFERROR(AS6/AR6,"") | AU6: =SUMIFS('Diário de estudo'!H3:H530,'Diário de estudo'!D3:D530,$A6,'Diário de estudo'!A3:A530,">="&DATE(2026,12,28),'Diário de estudo'!A3:A530,"<="&DATE(2027,1,3)) | AV6: =SUMIFS('Diário de estudo'!I3:I530,'Diário de estudo'!D3:D530,$A6,'Diário de estudo'!A3:A530,">="&DATE(2026,12,28),'Diário de estudo'!A3:A530,"<="&DATE(2027,1,3)) | AW6: =IFERROR(AV6/AU6,"")
A7: LEGISLAÇÃO INSTITUCIONAL MP | B7: =SUMIFS('Diário de estudo'!H3:H530,'Diário de estudo'!D3:D530,$A7,'Diário de estudo'!A3:A530,">="&DATE(2026,9,14),'Diário de estudo'!A3:A530,"<="&DATE(2026,9,20)) | C7: =SUMIFS('Diário de estudo'!I3:I530,'Diário de estudo'!D3:D530,$A7,'Diário de estudo'!A3:A530,">="&DATE(2026,9,14),'Diário de estudo'!A3:A530,"<="&DATE(2026,9,20)) | D7: =IFERROR(C7/B7,"") | E7: =SUMIFS('Diário de estudo'!H3:H530,'Diário de estudo'!D3:D530,$A7,'Diário de estudo'!A3:A530,">="&DATE(2026,9,21),'Diário de estudo'!A3:A530,"<="&DATE(2026,9,27)) | F7: =SUMIFS('Diário de estudo'!I3:I530,'Diário de estudo'!D3:D530,$A7,'Diário de estudo'!A3:A530,">="&DATE(2026,9,21),'Diário de estudo'!A3:A530,"<="&DATE(2026,9,27)) | G7: =IFERROR(F7/E7,"") | H7: =SUMIFS('Diário de estudo'!H3:H530,'Diário de estudo'!D3:D530,$A7,'Diário de estudo'!A3:A530,">="&DATE(2026,9,28),'Diário de estudo'!A3:A530,"<="&DATE(2026,10,4)) | I7: =SUMIFS('Diário de estudo'!I3:I530,'Diário de estudo'!D3:D530,$A7,'Diário de estudo'!A3:A530,">="&DATE(2026,9,28),'Diário de estudo'!A3:A530,"<="&DATE(2026,10,4)) | J7: =IFERROR(I7/H7,"") | K7: =SUMIFS('Diário de estudo'!H3:H530,'Diário de estudo'!D3:D530,$A7,'Diário de estudo'!A3:A530,">="&DATE(2026,10,5),'Diário de estudo'!A3:A530,"<="&DATE(2026,10,11)) | L7: =SUMIFS('Diário de estudo'!I3:I530,'Diário de estudo'!D3:D530,$A7,'Diário de estudo'!A3:A530,">="&DATE(2026,10,5),'Diário de estudo'!A3:A530,"<="&DATE(2026,10,11)) | M7: =IFERROR(L7/K7,"") | N7: =SUMIFS('Diário de estudo'!H3:H530,'Diário de estudo'!D3:D530,$A7,'Diário de estudo'!A3:A530,">="&DATE(2026,10,12),'Diário de estudo'!A3:A530,"<="&DATE(2026,10,18)) | O7: =SUMIFS('Diário de estudo'!I3:I530,'Diário de estudo'!D3:D530,$A7,'Diário de estudo'!A3:A530,">="&DATE(2026,10,12),'Diário de estudo'!A3:A530,"<="&DATE(2026,10,18)) | P7: =IFERROR(O7/N7,"") | Q7: =SUMIFS('Diário de estudo'!H3:H530,'Diário de estudo'!D3:D530,$A7,'Diário de estudo'!A3:A530,">="&DATE(2026,10,19),'Diário de estudo'!A3:A530,"<="&DATE(2026,10,25)) | R7: =SUMIFS('Diário de estudo'!I3:I530,'Diário de estudo'!D3:D530,$A7,'Diário de estudo'!A3:A530,">="&DATE(2026,10,19),'Diário de estudo'!A3:A530,"<="&DATE(2026,10,25)) | S7: =IFERROR(R7/Q7,"") | T7: =SUMIFS('Diário de estudo'!H3:H530,'Diário de estudo'!D3:D530,$A7,'Diário de estudo'!A3:A530,">="&DATE(2026,10,26),'Diário de estudo'!A3:A530,"<="&DATE(2026,11,1)) | U7: =SUMIFS('Diário de estudo'!I3:I530,'Diário de estudo'!D3:D530,$A7,'Diário de estudo'!A3:A530,">="&DATE(2026,10,26),'Diário de estudo'!A3:A530,"<="&DATE(2026,11,1)) | V7: =IFERROR(U7/T7,"") | W7: =SUMIFS('Diário de estudo'!H3:H530,'Diário de estudo'!D3:D530,$A7,'Diário de estudo'!A3:A530,">="&DATE(2026,11,2),'Diário de estudo'!A3:A530,"<="&DATE(2026,11,8)) | X7: =SUMIFS('Diário de estudo'!I3:I530,'Diário de estudo'!D3:D530,$A7,'Diário de estudo'!A3:A530,">="&DATE(2026,11,2),'Diário de estudo'!A3:A530,"<="&DATE(2026,11,8)) | Y7: =IFERROR(X7/W7,"") | Z7: =SUMIFS('Diário de estudo'!H3:H530,'Diário de estudo'!D3:D530,$A7,'Diário de estudo'!A3:A530,">="&DATE(2026,11,9),'Diário de estudo'!A3:A530,"<="&DATE(2026,11,15)) | AA7: =SUMIFS('Diário de estudo'!I3:I530,'Diário de estudo'!D3:D530,$A7,'Diário de estudo'!A3:A530,">="&DATE(2026,11,9),'Diário de estudo'!A3:A530,"<="&DATE(2026,11,15)) | AB7: =IFERROR(AA7/Z7,"") | AC7: =SUMIFS('Diário de estudo'!H3:H530,'Diário de estudo'!D3:D530,$A7,'Diário de estudo'!A3:A530,">="&DATE(2026,11,16),'Diário de estudo'!A3:A530,"<="&DATE(2026,11,22)) | AD7: =SUMIFS('Diário de estudo'!I3:I530,'Diário de estudo'!D3:D530,$A7,'Diário de estudo'!A3:A530,">="&DATE(2026,11,16),'Diário de estudo'!A3:A530,"<="&DATE(2026,11,22)) | AE7: =IFERROR(AD7/AC7,"") | AF7: =SUMIFS('Diário de estudo'!H3:H530,'Diário de estudo'!D3:D530,$A7,'Diário de estudo'!A3:A530,">="&DATE(2026,11,23),'Diário de estudo'!A3:A530,"<="&DATE(2026,11,29)) | AG7: =SUMIFS('Diário de estudo'!I3:I530,'Diário de estudo'!D3:D530,$A7,'Diário de estudo'!A3:A530,">="&DATE(2026,11,23),'Diário de estudo'!A3:A530,"<="&DATE(2026,11,29)) | AH7: =IFERROR(AG7/AF7,"") | AI7: =SUMIFS('Diário de estudo'!H3:H530,'Diário de estudo'!D3:D530,$A7,'Diário de estudo'!A3:A530,">="&DATE(2026,11,30),'Diário de estudo'!A3:A530,"<="&DATE(2026,12,6)) | AJ7: =SUMIFS('Diário de estudo'!I3:I530,'Diário de estudo'!D3:D530,$A7,'Diário de estudo'!A3:A530,">="&DATE(2026,11,30),'Diário de estudo'!A3:A530,"<="&DATE(2026,12,6)) | AK7: =IFERROR(AJ7/AI7,"") | AL7: =SUMIFS('Diário de estudo'!H3:H530,'Diário de estudo'!D3:D530,$A7,'Diário de estudo'!A3:A530,">="&DATE(2026,12,7),'Diário de estudo'!A3:A530,"<="&DATE(2026,12,13)) | AM7: =SUMIFS('Diário de estudo'!I3:I530,'Diário de estudo'!D3:D530,$A7,'Diário de estudo'!A3:A530,">="&DATE(2026,12,7),'Diário de estudo'!A3:A530,"<="&DATE(2026,12,13)) | AN7: =IFERROR(AM7/AL7,"") | AO7: =SUMIFS('Diário de estudo'!H3:H530,'Diário de estudo'!D3:D530,$A7,'Diário de estudo'!A3:A530,">="&DATE(2026,12,14),'Diário de estudo'!A3:A530,"<="&DATE(2026,12,20)) | AP7: =SUMIFS('Diário de estudo'!I3:I530,'Diário de estudo'!D3:D530,$A7,'Diário de estudo'!A3:A530,">="&DATE(2026,12,14),'Diário de estudo'!A3:A530,"<="&DATE(2026,12,20)) | AQ7: =IFERROR(AP7/AO7,"") | AR7: =SUMIFS('Diário de estudo'!H3:H530,'Diário de estudo'!D3:D530,$A7,'Diário de estudo'!A3:A530,">="&DATE(2026,12,21),'Diário de estudo'!A3:A530,"<="&DATE(2026,12,27)) | AS7: =SUMIFS('Diário de estudo'!I3:I530,'Diário de estudo'!D3:D530,$A7,'Diário de estudo'!A3:A530,">="&DATE(2026,12,21),'Diário de estudo'!A3:A530,"<="&DATE(2026,12,27)) | AT7: =IFERROR(AS7/AR7,"") | AU7: =SUMIFS('Diário de estudo'!H3:H530,'Diário de estudo'!D3:D530,$A7,'Diário de estudo'!A3:A530,">="&DATE(2026,12,28),'Diário de estudo'!A3:A530,"<="&DATE(2027,1,3)) | AV7: =SUMIFS('Diário de estudo'!I3:I530,'Diário de estudo'!D3:D530,$A7,'Diário de estudo'!A3:A530,">="&DATE(2026,12,28),'Diário de estudo'!A3:A530,"<="&DATE(2027,1,3)) | AW7: =IFERROR(AV7/AU7,"")
